Workbook
Name CurMonth: 'FACTORY COST'!$G$2
Name CurYear: 'FACTORY COST'!$BW$7
Name ProductionRRT: 'MFG COST SUMMARY'!$J$134
Name ProductionVolume: 'MFG COST SUMMARY'!$F$134
Name PrvMonthProductionRRT: 'FACTORY COST'!$AI$3

Sheet Guideline
A1: Guideline
A3: A. Data
B4: 1. STD:
C5: - Periodic: update new standard cost by Jan & Jul (if any)
C6: - Monthly: update additional product cost
B7: 2. ZVF59 (sheet has name of month: Jan, Feb…):
C8: - Check account 911330: balance is zero
C9: - Check & confirm all documents have been posted into system
C10: - Export data by T-code ZVF59 and copy to sheet of each month
M11: Document type: ZT (default)
M12: WIP Account: 132000 (default)
M13: Posting Date for Transfer, Posting Date: input as month period
M14: Exclusive Document Type: ZT (default)
M15: G/L Account: there was default manufactoring cost accounts (VAS 621 - 627). Add new account if any
M16: Functional Area:
M27: Download file: Location to save exported ZVF59 txt file
B32: 3. Direct material (sheet Tire Weight, DM-Sum)
C33: - Update theoretical DM from file DM calculation
C34: - Update Tyre weight tolerance from TS dept.
B35: 4. Rework tire
C36: - Update rework tire data from below link
C37: Rework tire 2023
B38: 5. Budget
C39: - Update budget (OB/RBAC) production volume and RRT
A41: B. Calculation
B42: 1. FACTORY COST
C43: - Choose month (refer to name CurMonth), year (refer to CurYear)
C44: - Update Production RRT of previous month (refer to name PrvMonthProductionRRT) to check gap vs previous month
C45: - Update budget (OB/RBAC) data in columns AT -> BE
C46: - Ensure total amount transfer in ZVF59 equal total actual amount in Factory cost:
D47: If amounts are different, please check:
D48: + New/change account number
D49: + Check formulas of sheet "Factory cost"
C50: - Check and comment for gap of each item (vs OB/RBAC and vs Previous month)
B51: 2. MFG COST SUMMARY
C52: - Update products produced in month based on FG inventory report
C53: Note: insert new line upper last product line to maintain sum formula
C54: - Check and comment for all gap and different trend
C55: - Update Ticket production volume and RRT (from PP-IE)
B56: 3. COGM upload
...

Sheet Data

Sheet STD
B1: BTMV 2024 Standard
B2: Update std in Jan & Jul
B3: \\10.118.29.7\BTMV-Data\4-ACCOUNTING\71.Costing\5.Standard & TPL\TPL\2023\Additional\ | P3: 2023 OB
P4: DM | T4: CC | U4: WS | V4: FC | W4: OPEX% | X4: Royalty% | Z4: TPL price
C5: BPC | D5: Description | E5: LI/SP | F5: Section | G5: Rim | H5: Pattern | I5: Brand name | J5: Brand category | K5: MTP group | L5: BTMV code | M5: M3 | N5: Tire weight g/tire | O5: RRW g/tire | Q5: LB | R5: Dep. | S5: Other | X5: BSJ | Y5: BSCAP | Z5: BSJ | AA5: BSCAP
C6: 300105689 | D6: 81W 195/45R17 RE005 | E6: 81W | F6: 195/45 | G6: 17 | H6: RE005 | I6: BRIDGESTONE | J6: BS | K6: PSR2 | M6: 0.056456094 | N6: 8832 | O6: 4115 | P6: 19.434096 | Q6: 5.6798664 | R6: 7.7709226 | S6: 6.9204876 | T6: 20.371277 | U6: 0.54031432 | V6: 40.345687 | W6: 0.047 | X6: 0 | Y6: 0.04 | Z6: 43.71 | AA6: 45.69 | AB6: =V6-P6-Q6-R6-S6-U6 -> 2.4424907e-15 | AC6: =T6-SUM(Q6:S6) -> 0
C7: 300105830 | D7: 96W 225/45R19 RE005 | E7: 96W | F7: 225/45 | G7: 19 | H7: RE005 | I7: BRIDGESTONE | J7: BS | K7: PSR2 | M7: 0.082901065 | N7: 12566 | O7: 5887 | P7: 26.65072 | Q7: 7.0321532 | R7: 9.5062235 | S7: 8.7901863 | T7: 25.328563 | U7: 0.76874884 | V7: 52.748032 | W7: 0.047 | X7: 0 | Y7: 0.04 | Z7: 57.15 | AA7: 59.74 | AB7: =V7-P7-Q7-R7-S7-U7 -> -2.553513e-15 | AC7: =T7-SUM(Q7:S7) -> 0
C8: 300110512 | D8: 93W 215/45R18 PT005A | E8: 93W | F8: 215/45 | G8: 18 | H8: PT005A | I8: BRIDGESTONE | J8: BS | K8: PSR2 | M8: 0.071461105 | N8: 12295 | O8: 5722 | P8: 23.51189 | Q8: 6.5702044 | R8: 8.6541574 | S8: 8.0078482 | T8: 23.23221 | U8: 0.7521699 | V8: 47.49627 | W8: 0.047 | X8: 0 | Y8: 0.04 | Z8: 51.46 | AA8: 53.79 | AB8: =V8-P8-Q8-R8-S8-U8 -> 9.9920072e-16 | AC8: =T8-SUM(Q8:S8) -> 0
C9: 300115807 | D9: 93W 215/45R18 PT005A | E9: 93W | F9: 215/45 | G9: 18 | H9: PT005A | I9: BRIDGESTONE | J9: BS | K9: PSR2 | M9: 0.071461105 | N9: 11009 | O9: 4809 | P9: 23.588244 | Q9: 6.2719431 | R9: 8.6882074 | S9: 7.9301246 | T9: 22.890275 | U9: 0.67349642 | V9: 47.152015 | W9: 0.047 | X9: 0 | Y9: 0.04 | Z9: 51.09 | AA9: 53.4 | AB9: =V9-P9-Q9-R9-S9-U9 -> -3.8857806e-15 | AC9: =T9-SUM(Q9:S9) -> 0
C10: 300119530 | D10: 91V 205/55R16 P-EP15 | E10: 91V | F10: 205/55 | G10: 16 | H10: P-EP15 | I10: BRIDGESTONE | J10: BS | K10: PSR3 | M10: 0.064256968 | N10: 10090 | O10: 4832 | P10: 19.877298 | Q10: 5.9375767 | R10: 7.6737609 | S10: 7.0057664 | T10: 20.617104 | U10: 0.61727485 | V10: 41.111677 | W10: 0.047 | X10: 0 | Y10: 0.04 | Z10: 44.54 | AA10: 46.56 | AB10: =V10-P10-Q10-R10-S10-U10 -> -2.220446e-15 | AC10: =T10-SUM(Q10:S10) -> 0
C11: 300123416 | D11: 96H 215/60R17 EL64Z | E11: 96H | F11: 215/60 | G11: 17 | H11: EL64Z | I11: BRIDGESTONE | J11: BS | K11: PSR2 | M11: 0.080307202 | N11: 12313 | O11: 5583 | P11: 26.280589 | Q11: 6.6133977 | R11: 8.7613298 | S11: 8.1493412 | T11: 23.524069 | U11: 0.75327109 | V11: 50.557929 | W11: 0.047 | X11: 0 | Y11: 0.04 | Z11: 54.78 | AA11: 57.26 | AB11: =V11-P11-Q11-R11-S11-U11 -> 2.6645353e-15 | AC11: =T11-SUM(Q11:S11) -> 0
C12: 300123417 | D12: 95V 215/55R18 DTH1AZ | E12: 95V | F12: 215/55 | G12: 18 | H12: DTH1AZ | I12: BRIDGESTONE | J12: BS | K12: PSR2 | M12: 0.081217853 | N12: 12073 | O12: 5650 | P12: 24.230519 | Q12: 6.7748712 | R12: 9.1917312 | S12: 8.4601627 | T12: 24.426765 | U12: 0.73858863 | V12: 49.395873 | W12: 0.047 | X12: 0 | Y12: 0.04 | Z12: 53.52 | AA12: 55.94 | AB12: =V12-P12-Q12-R12-S12-U12 -> -9.2148511e-15 | AC12: =T12-SUM(Q12:S12) -> 0
C13: 300123424 | D13: 245/45R20 AL011Z | F13: 245/45 | G13: 20 | H13: AL011Z | I13: BRIDGESTONE | J13: BS | K13: PSR2 | M13: 0.10206923 | N13: 15095 | O13: 6959 | P13: 31.903354 | Q13: 7.9098713 | R13: 10.565309 | S13: 9.946525 | T13: 28.421706 | U13: 0.92346521 | V13: 61.248525 | W13: 0.047 | X13: 0 | Y13: 0.04 | Z13: 66.36 | AA13: 69.36 | AB13: =V13-P13-Q13-R13-S13-U13 -> 6.2172489e-15 | AC13: =T13-SUM(Q13:S13) -> 0
C14: 300123425 | D14: 225/55R19 AL011Z | F14: 225/55 | G14: 19 | H14: AL011Z | I14: BRIDGESTONE | J14: BS | K14: PSR2 | M14: 0.094149252 | N14: 12566 | O14: 5887 | P14: 26.648953 | Q14: 7.0321532 | R14: 9.5062235 | S14: 8.7901863 | T14: 25.328563 | U14: 0.76874884 | V14: 52.746265 | W14: 0.047 | X14: 0 | Y14: 0.04 | Z14: 57.15 | AA14: 59.74 | AB14: =V14-P14-Q14-R14-S14-U14 -> -6.1062266e-15 | AC14: =T14-SUM(Q14:S14) -> 0
C15: 300125819 | D15: 99V 225/55R19 AL01 | E15: 99V | F15: 225/55 | G15: 19 | H15: AL01 | I15: BRIDGESTONE | J15: BS | K15: PSR2 | M15: 0.094149252 | N15: 12566 | O15: 5887 | P15: 26.646953 | Q15: 7.0321532 | R15: 9.5062235 | S15: 8.7901863 | T15: 25.328563 | U15: 0.76874884 | V15: 52.744265 | W15: 0.047 | X15: 0 | Y15: 0.04 | Z15: 57.14 | AA15: 59.73 | AB15: =V15-P15-Q15-R15-S15-U15 -> -2.7755576e-15 | AC15: =T15-SUM(Q15:S15) -> 0
C16: 300125820 | D16: 101W 235/55R19 AL01 | E16: 101W | F16: 235/55 | G16: 19 | H16: AL01 | I16: BRIDGESTONE | J16: BS | K16: PSR2 | M16: 0.10131906 | N16: 13665 | O16: 6288 | P16: 29.182018 | Q16: 7.452603 | R16: 10.013683 | S16: 9.367666 | T16: 26.833952 | U16: 0.83598225 | V16: 56.851952 | W16: 0.047 | X16: 0 | Y16: 0.04 | Z16: 61.59 | AA16: 64.38 | AB16: =V16-P16-Q16-R16-S16-U16 -> 1.4432899e-15 | AC16: =T16-SUM(Q16:S16) -> 0
C17: PSR0V01B | D17: 79S 155/80R13 SL10Z | E17: 79S | F17: 155/80 | G17: 13 | H17: SL10Z | I17: SEIBERLING | J17: FS&D | K17: PSR5 | L17: GSGVA | M17: 0.040677807 | N17: 5367 | O17: 2520 | P17: 10.498264 | Q17: 4.1208603 | R17: 5.3369935 | S17: 4.5629747 | T17: 14.020829 | U17: 0.32833639 | V17: 24.847428 | W17: 0.047 | X17: 0.0025 | Y17: 0.0325 | Z17: 26.99 | AA17: 27.9 | AB17: =V17-P17-Q17-R17-S17-U17 -> 3.4972025e-15 | AC17: =T17-SUM(Q17:S17) -> 0
C18: PSR0V01P | D18: 82H 175/65R14 BAR3Z | E18: 82H | F18: 175/65 | G18: 14 | H18: BAR3Z | I18: BOB JANE | J18: Others | K18: PSR5 | L18: R2DVA | M18: 0.046708271 | N18: 6435 | O18: 3133 | P18: 12.268556 | Q18: 4.5634788 | R18: 6.0224413 | S18: 5.2321611 | T18: 15.818081 | U18: 0.39367331 | V18: 28.48031 | W18: 0.047 | X18: 0 | Y18: 0.03 | Z18: 30.86 | AA18: 31.89 | AB18: =V18-P18-Q18-R18-S18-U18 -> 3.4972025e-15 | AC18: =T18-SUM(Q18:S18) -> 0
C19: PSR0V01S | D19: 82H 175/65R14 SPCZ | E19: 82H | F19: 175/65 | G19: 14 | H19: SPCZ | I19: SUPERCAT | J19: Others | K19: PSR5 | L19: P2PVA | M19: 0.046708271 | N19: 7043 | O19: 3404 | P19: 13.651433 | Q19: 4.7381973 | R19: 6.2042895 | S19: 5.4533965 | T19: 16.395883 | U19: 0.43086886 | V19: 30.478185 | W19: 0.047 | X19: 0 | Y19: 0.03 | Z19: 33.02 | AA19: 34.13 | AB19: =V19-P19-Q19-R19-S19-U19 -> -3.663736e-15 | AC19: =T19-SUM(Q19:S19) -> 0
C20: PSR0V02P | D20: 95H 205/65R15 BAR3Z | E20: 95H | F20: 205/65 | G20: 15 | H20: BAR3Z | I20: BOB JANE | J20: Others | K20: PSR4 | L20: QP3VA | M20: 0.067468812 | N20: 8892 | O20: 4138 | P20: 17.492648 | Q20: 5.2585929 | R20: 6.9017625 | S20: 6.2427863 | T20: 18.403142 | U20: 0.54398494 | V20: 36.439775 | W20: 0.047 | X20: 0 | Y20: 0.03 | Z20: 39.48 | AA20: 40.81 | AB20: =V20-P20-Q20-R20-S20-U20 -> 0 | AC20: =T20-SUM(Q20:S20) -> 0
C21: PSR0V03P | D21: 95V 215/60R16 BAR3Z | E21: 95V | F21: 215/60 | G21: 16 | H21: BAR3Z | I21: BOB JANE | J21: Others | K21: PSR3 | L21: BJTVA | M21: 0.074501903 | N21: 10023 | O21: 4806 | P21: 19.512107 | Q21: 5.7764243 | R21: 7.6670462 | S21: 7.0383375 | T21: 20.481808 | U21: 0.613176 | V21: 40.607091 | W21: 0.047 | X21: 0 | Y21: 0.03 | Z21: 43.99 | AA21: 45.47 | AB21: =V21-P21-Q21-R21-S21-U21 -> -4.4408921e-15 | AC21: =T21-SUM(Q21:S21) -> 0
C22: PSR0V03S | D22: 86H 185/65R14 SPCZ | E22: 86H | F22: 185/65 | G22: 14 | H22: SPCZ | I22: SUPERCAT | J22: Others | K22: PSR5 | L22: VVVVA | M22: 0.051603556 | N22: 7502 | O22: 3592 | P22: 14.562613 | Q22: 4.8958896 | R22: 6.4574514 | S22: 5.7103715 | T22: 17.063712 | U22: 0.45894905 | V22: 32.085275 | W22: 0.047 | X22: 0 | Y22: 0.03 | Z22: 34.76 | AA22: 35.93 | AB22: =V22-P22-Q22-R22-S22-U22 -> 7.8270723e-15 | AC22: =T22-SUM(Q22:S22) -> 0
C23: PSR0V04S | D23: 88H 195/60R15 SPCZ | E23: 88H | F23: 195/60 | G23: 15 | H23: SPCZ | I23: SUPERCAT | J23: Others | K23: PSR4 | L23: 3MCVA | M23: 0.057896792 | N23: 8461 | O23: 4040 | P23: 16.360694 | Q23: 5.1693219 | R23: 6.7486861 | S23: 6.0492842 | T23: 17.967292 | U23: 0.51761769 | V23: 34.845604 | W23: 0.047 | X23: 0 | Y23: 0.03 | Z23: 37.75 | AA23: 39.02 | AB23: =V23-P23-Q23-R23-S23-U23 -> 2.9976022e-15 | AC23: =T23-SUM(Q23:S23) -> 0
C24: PSR0V05B | D24: 88S 185/65R15 SL10Z | E24: 88S | F24: 185/65 | G24: 15 | H24: SL10Z | I24: SEIBERLING | J24: FS&D | K24: PSR4 | L24: EHSVA | M24: 0.056094935 | N24: 7509 | O24: 3497 | P24: 14.796449 | Q24: 4.9094159 | R24: 6.2805441 | S24: 5.5627509 | T24: 16.752711 | U24: 0.45937729 | V24: 32.008537 | W24: 0.047 | X24: 0.0025 | Y24: 0.0325 | Z24: 34.77 | AA24: 35.94 | AB24: =V24-P24-Q24-R24-S24-U24 -> -7.6605389e-15 | AC24: =T24-SUM(Q24:S24) -> 0
C25: PSR0V05P | D25: 88H 185/65R15 BAR3Z | E25: 88H | F25: 185/65 | G25: 15 | H25: BAR3Z | I25: BOB JANE | J25: Others | K25: PSR4 | L25: JZTVA | M25: 0.056094935 | N25: 7506 | O25: 3648 | P25: 14.326674 | Q25: 4.8805642 | R25: 6.4500862 | S25: 5.697528 | T25: 17.028178 | U25: 0.45919376 | V25: 31.814046 | W25: 0.047 | X25: 0 | Y25: 0.03 | Z25: 34.47 | AA25: 35.63 | AB25: =V25-P25-Q25-R25-S25-U25 -> -5.7176486e-15 | AC25: =T25-SUM(Q25:S25) -> 0
C26: PSR0V05S | D26: 91H 195/65R15 SPCZ | E26: 91H | F26: 195/65 | G26: 15 | H26: SPCZ | I26: SUPERCAT | J26: Others | K26: PSR4 | L26: YYYVA | M26: 0.061626503 | N26: 8584 | O26: 4086 | P26: 16.617401 | Q26: 5.1823032 | R26: 6.8236052 | S26: 6.1345046 | T26: 18.140413 | U26: 0.52514245 | V26: 35.282957 | W26: 0.047 | X26: 0 | Y26: 0.03 | Z26: 38.23 | AA26: 39.51 | AB26: =V26-P26-Q26-R26-S26-U26 -> -9.9920072e-16 | AC26: =T26-SUM(Q26:S26) -> 0
C27: PSR0V06P | D27: 84H 185/60R15 BAR3Z | E27: 84H | F27: 185/60 | G27: 15 | H27: BAR3Z | I27: BOB JANE | J27: Others | K27: PSR4 | L27: WBPVA | M27: 0.052805117 | N27: 7386 | O27: 3583 | P27: 14.069269 | Q27: 4.8358962 | R27: 6.5506707 | S27: 5.7690098 | T27: 17.155577 | U27: 0.45185253 | V27: 31.676699 | W27: 0.047 | X27: 0 | Y27: 0.03 | Z27: 34.32 | AA27: 35.47 | AB27: =V27-P27-Q27-R27-S27-U27 -> -7.7715612e-16 | AC27: =T27-SUM(Q27:S27) -> 0
C28: PSR0V07S | D28: 95V 215/60R16 SPCZ | E28: 95V | F28: 215/60 | G28: 16 | H28: SPCZ | I28: SUPERCAT | J28: Others | K28: PSR3 | L28: F91VA | M28: 0.074501903 | N28: 10732 | O28: 5097 | P28: 21.181023 | Q28: 5.9755221 | R28: 7.7986882 | S28: 7.2104738 | T28: 20.984684 | U28: 0.65655042 | V28: 42.822257 | W28: 0.047 | X28: 0 | Y28: 0.03 | Z28: 46.39 | AA28: 47.95 | AB28: =V28-P28-Q28-R28-S28-U28 -> -2.220446e-15 | AC28: =T28-SUM(Q28:S28) -> 0
... C41: PSR0V13D | D41: 102V 225/65R17 DTH1AZ | E41: 102V | F41: 225/65 | G41: 17 | H41: DTH1AZ | I41: DAYTON | J41: FS&D | K41: PSR2 | L41: AMMZA | M41: 0.092659328 | N41: 12352 | O41: 5741 | P41: 24.465164 | Q41: 6.7996527 | R41: 8.7557017 | S41: 8.1510522 | T41: 23.706407 | U41: 0.75565699 | V41: 48.927227 | W41: 0.047 | X41: 0.0025 | Y41: 0.0325 | Z41: 53.15 | AA41: 54.94 | AB41: =V41-P41-Q41-R41-S41-U41 -> 0 | AC41: =T41-SUM(Q41:S41) -> 0
C42: PSR0V143 | D42: 175/50R15 150KZ | F42: 175/50 | G42: 15 | H42: 150KZ | I42: BRIDGESTONE | J42: BS | K42: PSR4 | L42: KCEVA | M42: 0.042467558 | N42: 6951 | O42: 3383 | P42: 13.622983 | Q42: 4.7963971 | R42: 6.7727014 | S42: 5.9258298 | T42: 17.494928 | U42: 0.42524059 | V42: 31.543152 | W42: 0.047 | X42: 0 | Y42: 0.04 | Z42: 34.17 | AA42: 35.72 | AB42: =V42-P42-Q42-R42-S42-U42 -> -2.553513e-15 | AC42: =T42-SUM(Q42:S42) -> 0
C43: PSR0V145 | D43: 98V 225/60R16 EP3AZ | E43: 98V | F43: 225/60 | G43: 16 | H43: EP3AZ | I43: BRIDGESTONE | J43: BS | K43: PSR3 | L43: KPXVA | M43: 0.080808933 | N43: 9731 | O43: 4767 | P43: 20.175765 | Q43: 5.7498507 | R43: 7.7718118 | S43: 7.1095965 | T43: 20.631259 | U43: 0.59531235 | V43: 41.402336 | W43: 0.047 | X43: 0 | Y43: 0.04 | Z43: 44.86 | AA43: 46.89 | AB43: =V43-P43-Q43-R43-S43-U43 -> 0 | AC43: =T43-SUM(Q43:S43) -> 0
C44: PSR0V14D | D44: 108V 235/65R17 DTH1AZ | E44: 108V | F44: 235/65 | G44: 17 | H44: DTH1AZ | I44: DAYTON | J44: FS&D | K44: PSR2 | L44: LCDZA | M44: 0.10028269 | N44: 13460 | O44: 6300 | P44: 26.97937 | Q44: 7.1210799 | R44: 9.3587767 | S44: 8.7692267 | T44: 25.249083 | U44: 0.82344098 | V44: 53.051894 | W44: 0.047 | X44: 0.0025 | Y44: 0.0325 | Z44: 57.63 | AA44: 59.58 | AB44: =V44-P44-Q44-R44-S44-U44 -> -1.8873791e-15 | AC44: =T44-SUM(Q44:S44) -> 0
C45: PSR0V150 | D45: 185/70R13 150EZ | F45: 185/70 | G45: 13 | H45: 150EZ | I45: BRIDGESTONE | J45: BS | K45: PSR5 | L45: ADXVA | M45: 0.069302044 | N45: 6682 | O45: 3258 | P45: 13.251737 | Q45: 4.576501 | R45: 6.2553497 | S45: 5.5474272 | T45: 16.379278 | U45: 0.408784 | V45: 30.039799 | W45: 0.047 | X45: 0 | Y45: 0.04 | Z45: 32.55 | AA45: 34.02 | AB45: =V45-P45-Q45-R45-S45-U45 -> -1.9984014e-15 | AC45: =T45-SUM(Q45:S45) -> 0
C46: PSR0V151 | D46: 079S 165/65R14 150EZ | E46: 079S | F46: 165/65 | G46: 14 | H46: 150EZ | I46: BRIDGESTONE | J46: BS | K46: PSR5 | L46: RBMVA | M46: 0.04209744 | N46: 6154 | O46: 2989 | P46: 12.159812 | Q46: 4.5374844 | R46: 6.404158 | S46: 5.5691661 | T46: 16.510808 | U46: 0.3764826 | V46: 29.047103 | W46: 0.047 | X46: 0 | Y46: 0.04 | Z46: 31.47 | AA46: 32.9 | AB46: =V46-P46-Q46-R46-S46-U46 -> 6.1617378e-15 | AC46: =T46-SUM(Q46:S46) -> 0
C47: PSR0V152 | D47: 079S 165/70R13 150EZ | E47: 079S | F47: 165/70 | G47: 13 | H47: 150EZ | I47: BRIDGESTONE | J47: BS | K47: PSR5 | L47: ECCVA | M47: 0.040793308 | N47: 5603 | O47: 2729 | P47: 11.137326 | Q47: 4.2505776 | R47: 5.7836344 | S47: 5.0055806 | T47: 15.039793 | U47: 0.34277413 | V47: 26.519892 | W47: 0.047 | X47: 0 | Y47: 0.04 | Z47: 28.73 | AA47: 30.03 | AB47: =V47-P47-Q47-R47-S47-U47 -> 1.2212453e-15 | AC47: =T47-SUM(Q47:S47) -> 0
C48: PSR0V15D | D48: 96H 215/60R17 DTH1AZ | E48: 96H | F48: 215/60 | G48: 17 | H48: DTH1AZ | I48: DAYTON | J48: FS&D | K48: PSR2 | L48: 7DTMA | M48: 0.080307202 | N48: 10819 | O48: 5070 | P48: 20.493922 | Q48: 6.1399529 | R48: 7.9502052 | S48: 7.2712386 | T48: 21.361397 | U48: 0.66187281 | V48: 42.517192 | W48: 0.047 | X48: 0.0025 | Y48: 0.0325 | Z48: 46.19 | AA48: 47.75 | AB48: =V48-P48-Q48-R48-S48-U48 -> 4.4408921e-15 | AC48: =T48-SUM(Q48:S48) -> 0
C49: PSR0V164 | D49: 235/40R18 EL64AZ | F49: 235/40 | G49: 18 | H49: EL64AZ | I49: BRIDGESTONE | J49: BS | K49: PSR2 | L49: SCLZA | M49: 0.076793814 | N49: 11557 | O49: 5130 | P49: 24.574951 | Q49: 6.4162461 | R49: 8.7451835 | S49: 8.0443157 | T49: 23.205745 | U49: 0.70702136 | V49: 48.487717 | W49: 0.047 | X49: 0 | Y49: 0.04 | Z49: 52.53 | AA49: 54.91 | AB49: =V49-P49-Q49-R49-S49-U49 -> 0 | AC49: =T49-SUM(Q49:S49) -> 0
C50: PSR0V165 | D50: 84H 185/60R15 EL64Z | E50: 84H | F50: 185/60 | G50: 15 | H50: EL64Z | I50: BRIDGESTONE | J50: BS | K50: PSR4 | L50: ZJFVA | M50: 0.052805117 | N50: 8512 | O50: 4025 | P50: 17.616776 | Q50: 5.1736425 | R50: 6.8716595 | S50: 6.2188652 | T50: 18.264167 | U50: 0.52073772 | V50: 36.401681 | W50: 0.047 | X50: 0 | Y50: 0.04 | Z50: 39.44 | AA50: 41.23 | AB50: =V50-P50-Q50-R50-S50-U50 -> 3.1086245e-15 | AC50: =T50-SUM(Q50:S50) -> 0
C51: PSR0V166 | D51: 88H 185/65R15 EL64Z | E51: 88H | F51: 185/65 | G51: 15 | H51: EL64Z | I51: BRIDGESTONE | J51: BS | K51: PSR4 | L51: QWAVA | M51: 0.056094935 | N51: 8809 | O51: 4150 | P51: 18.355228 | Q51: 5.2501029 | R51: 6.908503 | S51: 6.2863018 | T51: 18.444908 | U51: 0.53890725 | V51: 37.339043 | W51: 0.047 | X51: 0 | Y51: 0.04 | Z51: 40.45 | AA51: 42.29 | AB51: =V51-P51-Q51-R51-S51-U51 -> -5.4400928e-15 | AC51: =T51-SUM(Q51:S51) -> 0
C52: PSR0V168 | D52: 91W 215/45R17 EL64AZ | E52: 91W | F52: 215/45 | G52: 17 | H52: EL64AZ | I52: BRIDGESTONE | J52: BS | K52: PSR2 | L52: JXKVA | M52: 0.06599104 | N52: 10209 | O52: 4579 | P52: 21.758714 | Q52: 6.0049302 | R52: 8.0622986 | S52: 7.3105992 | T52: 21.377828 | U52: 0.6245549 | V52: 43.761097 | W52: 0.047 | X52: 0 | Y52: 0.04 | Z52: 47.41 | AA52: 49.56 | AB52: =V52-P52-Q52-R52-S52-U52 -> 0 | AC52: =T52-SUM(Q52:S52) -> 0
...

Sheet Jan
A1: Kết xuất ZVF59 từ SAP, copy thay dữ liệu từ A2 -> BO210
A2: Creation Flag(1) | B2: Unit No. of slip(80) | C2: Posting Date(10) | D2: Document Date(10) | E2: Document Type(5) | F2: Reference(16) | G2: Doc. Header text(25) | H2: Currency(5) | I2: Exchange Rate(11) | J2: Translation Date(10) | K2: Posting Key(2) | L2: Account Code(17) | M2: G/L Account(10) | N2: Amount in Doc. Currency(14) | O2: Amount in Local Currency(14) | P2: Tax Base Amount in Document Currency(14) | Q2: Calculate tax(1) | R2: Tax Code(2) | S2: Payment Block(1) | T2: Payment Method(1) | U2: Business Place(4) | V2: Assignment(18) | W2: Text(50) | X2: Number of Invoice(10) | Y2: Fiscal Year of Relevant Invoice(4) | Z2: Line Item of Relevant Invoice(3) | AA2: Reference specification 1(12) | AB2: Reference specification 2(12) | AC2: Reference specification 3(20) | AD2: Material(18) | AE2: Cost center(10) | AF2: Internal Order(12) | AG2: Sales Order(10) | AH2: Sales Order Item(6) | AI2: Delivery Schedule for SO(4) | AJ2: Personnel number(8) | AK2: Plant(4) | AL2: Business Area(4) | AM2: Quantity(14) | AN2: Unit of Measure(3) | AO2: Profit Center(10) | AP2: Partner(10) | AQ2: Functional Area(4) | AR2: Purchase order(10) | AS2: Purchase order Item(5) | AT2: Baseline Date(10) | AU2: Value date(10) | AV2: Payment terms(4) | AW2: Cash Discount Days 1(3) | AX2: Cash Discount Percentage 1(6) | AY2: Cash Discount Days 2(3) | AZ2: Cash Discount Percentage 2(6) | BA2: Net Payment Terms Period(3) | BB2: Own Bank(5) | BC2: Bank Business Partners(4) | BD2: Instruction Key 1(2) | BE2: Instruction Key 2(2) | BF2: Instruction Key 3(2) | BG2: Instruction Key 4(2) | BH2: Payment Reference(30) | BI2: Payment currency amount(14) | BJ2: WHT Code(2) | BK2: WHT Base Amount(16) | BL2: WHT Amount(16) | BM2: SCB Indicator(3) | BN2: Supplying Country(3)
A3: 0 | B3: 1 | C3: 31.01.2024 | D3: 31.01.2024 | E3: ZT | G3: Transfer to WIP Jan-2024 | H3: USD | K3: 40 | L3: 132000 | N3: 6314761.3 | V3: Transfer to WIP | W3: Transfer to WIP 132000 | AL3: A01
A4: 0 | B4: 1 | K4: 50 | L4: 651110 | N4: 1830.46 | V4: Transfer to WIP | W4: Transfer to WIP 651110 62730401831U | AE4: 831U | AF4: 62730401831U | AL4: A01 | AO4: 99999
A5: 0 | B5: 1 | K5: 50 | L5: 651110 | N5: 3237.13 | V5: Transfer to WIP | W5: Transfer to WIP 651110 62730401832B | AE5: 832B | AF5: 62730401832B | AL5: A01 | AO5: 99999
A6: 0 | B6: 1 | K6: 50 | L6: 651110 | N6: 13819.41 | V6: Transfer to WIP | W6: Transfer to WIP 651110 62730401832C | AE6: 832C | AF6: 62730401832C | AL6: A01 | AO6: 99999
A7: 0 | B7: 1 | K7: 50 | L7: 651110 | N7: 37860.46 | V7: Transfer to WIP | W7: Transfer to WIP 651110 62730401832E | AE7: 832E | AF7: 62730401832E | AL7: A01 | AO7: 99999
A8: 0 | B8: 1 | K8: 50 | L8: 651110 | N8: 3461.26 | V8: Transfer to WIP | W8: Transfer to WIP 651110 62730401832F | AE8: 832F | AF8: 62730401832F | AL8: A01 | AO8: 99999
A9: 0 | B9: 1 | K9: 50 | L9: 651110 | N9: 10204.42 | V9: Transfer to WIP | W9: Transfer to WIP 651110 62730401832H | AE9: 832H | AF9: 62730401832H | AL9: A01 | AO9: 99999
A10: 0 | B10: 1 | K10: 50 | L10: 651110 | N10: 726.47 | V10: Transfer to WIP | W10: Transfer to WIP 651110 62730403832H | AE10: 832H | AF10: 62730403832H | AL10: A01 | AO10: 99999
A11: 0 | B11: 1 | K11: 50 | L11: 651110 | N11: 63161.51 | V11: Transfer to WIP | W11: Transfer to WIP 651110 62730401832J | AE11: 832J | AF11: 62730401832J | AL11: A01 | AO11: 99999
A12: 0 | B12: 1 | K12: 50 | L12: 651110 | N12: 4513.09 | V12: Transfer to WIP | W12: Transfer to WIP 651110 62730401832L | AE12: 832L | AF12: 62730401832L | AL12: A01 | AO12: 99999
A13: 0 | B13: 1 | K13: 50 | L13: 651110 | N13: 443.86 | V13: Transfer to WIP | W13: Transfer to WIP 651110 62730401851C | AE13: 851C | AF13: 62730401851C | AL13: A01 | AO13: 99999
A14: 0 | B14: 1 | K14: 50 | L14: 651110 | N14: 449.62 | V14: Transfer to WIP | W14: Transfer to WIP 651110 62730401851H | AE14: 851H | AF14: 62730401851H | AL14: A01 | AO14: 99999
A15: 0 | B15: 1 | K15: 50 | L15: 651110 | N15: 485.25 | V15: Transfer to WIP | W15: Transfer to WIP 651110 62730401851L | AE15: 851L | AF15: 62730401851L | AL15: A01 | AO15: 99999
A16: 0 | B16: 1 | K16: 50 | L16: 652210 | N16: 627.99 | V16: Transfer to WIP | W16: Transfer to WIP 652210 627706013221 | AE16: 3221 | AF16: 627706013221 | AL16: A01 | AO16: 99999
A17: 0 | B17: 1 | K17: 50 | L17: 652210 | N17: 1541.99 | V17: Transfer to WIP | W17: Transfer to WIP 652210 627706043221 | AE17: 3221 | AF17: 627706043221 | AL17: A01 | AO17: 99999
A18: 0 | B18: 1 | K18: 50 | L18: 652210 | N18: 650.92 | V18: Transfer to WIP | W18: Transfer to WIP 652210 627706013312 | AE18: 3312 | AF18: 627706013312 | AL18: A01 | AO18: 99999
A19: 0 | B19: 1 | K19: 50 | L19: 652210 | N19: 48046.86 | V19: Transfer to WIP | W19: Transfer to WIP 652210 627706018111 | AE19: 8111 | AF19: 627706018111 | AL19: A01 | AO19: 99999
A20: 0 | B20: 1 | K20: 50 | L20: 652210 | N20: 13092.77 | V20: Transfer to WIP | W20: Transfer to WIP 652210 627706018312 | AE20: 8312 | AF20: 627706018312 | AL20: A01 | AO20: 99999
A21: 0 | B21: 1 | K21: 50 | L21: 652210 | N21: 11452.61 | V21: Transfer to WIP | W21: Transfer to WIP 652210 62770605832E | AE21: 832E | AF21: 62770605832E | AL21: A01 | AO21: 99999
A22: 0 | B22: 1 | K22: 50 | L22: 652210 | N22: 16489.65 | V22: Transfer to WIP | W22: Transfer to WIP 652210 62770605832F | AE22: 832F | AF22: 62770605832F | AL22: A01 | AO22: 99999
A23: 0 | B23: 1 | K23: 50 | L23: 652210 | N23: 95.21 | V23: Transfer to WIP | W23: Transfer to WIP 652210 62770601832L | AE23: 832L | AF23: 62770601832L | AL23: A01 | AO23: 99999
A24: 0 | B24: 1 | K24: 50 | L24: 652210 | N24: 331.25 | V24: Transfer to WIP | W24: Transfer to WIP 652210 62770601851H | AE24: 851H | AF24: 62770601851H | AL24: A01 | AO24: 99999
A25: 0 | B25: 1 | K25: 50 | L25: 652210 | N25: 111.79 | V25: Transfer to WIP | W25: Transfer to WIP 652210 62770601851I | AE25: 851I | AF25: 62770601851I | AL25: A01 | AO25: 99999
A26: 0 | B26: 1 | K26: 50 | L26: 652210 | N26: 98.64 | V26: Transfer to WIP | W26: Transfer to WIP 652210 62770601851L | AE26: 851L | AF26: 62770601851L | AL26: A01 | AO26: 99999
A27: 0 | B27: 1 | K27: 50 | L27: 652210 | N27: 924.72 | V27: Transfer to WIP | W27: Transfer to WIP 652210 62770601852I | AE27: 852I | AF27: 62770601852I | AL27: A01 | AO27: 99999
A28: 0 | B28: 1 | K28: 50 | L28: 654010 | N28: 646233.09 | V28: Transfer to WIP | W28: Transfer to WIP 654010 627400011611 | AE28: 1611 | AF28: 627400011611 | AL28: A01 | AO28: 99999
A29: 0 | B29: 1 | K29: 50 | L29: 654010 | N29: 311905.35 | V29: Transfer to WIP | W29: Transfer to WIP 654010 627400021611 | AE29: 1611 | AF29: 627400021611 | AL29: A01 | AO29: 99999
A30: 0 | B30: 1 | K30: 50 | L30: 651110 | N30: 299.6 | V30: Transfer to WIP | W30: Transfer to WIP 651110 62730401321P | AE30: 321P | AF30: 62730401321P | AL30: A01 | AO30: 99999
A31: 0 | B31: 1 | K31: 50 | L31: 644100 | N31: 35.65 | V31: Transfer to WIP | W31: Transfer to WIP 644100 62720805851L | AE31: 851L | AF31: 62720805851L | AL31: A01 | AO31: 99999
A32: 0 | B32: 1 | K32: 50 | L32: 644100 | N32: 556.71 | V32: Transfer to WIP | W32: Transfer to WIP 644100 62720801852I | AE32: 852I | AF32: 62720801852I | AL32: A01 | AO32: 99999
A33: 0 | B33: 1 | K33: 50 | L33: 644100 | N33: 491.6 | V33: Transfer to WIP | W33: Transfer to WIP 644100 62720801852J | AE33: 852J | AF33: 62720801852J | AL33: A01 | AO33: 99999
A34: 0 | B34: 1 | K34: 50 | L34: 644100 | N34: 331.83 | V34: Transfer to WIP | W34: Transfer to WIP 644100 62720803852J | AE34: 852J | AF34: 62720803852J | AL34: A01 | AO34: 99999
A35: 0 | B35: 1 | K35: 50 | L35: 644100 | N35: 594.21 | V35: Transfer to WIP | W35: Transfer to WIP 644100 62720805852J | AE35: 852J | AF35: 62720805852J | AL35: A01 | AO35: 99999
A36: 0 | B36: 1 | K36: 50 | L36: 644100 | N36: 368.6 | V36: Transfer to WIP | W36: Transfer to WIP 644100 62720899852J | AE36: 852J | AF36: 62720899852J | AL36: A01 | AO36: 99999
A37: 0 | B37: 1 | K37: 50 | L37: 644500 | N37: 1121.94 | V37: Transfer to WIP | W37: Transfer to WIP 644500 627301021213 | AE37: 1213 | AF37: 627301021213 | AL37: A01 | AO37: 99999
A38: 0 | B38: 1 | K38: 50 | L38: 644500 | N38: 648 | V38: Transfer to WIP | W38: Transfer to WIP 644500 627301991213 | AE38: 1213 | AF38: 627301991213 | AL38: A01 | AO38: 99999
A39: 0 | B39: 1 | K39: 50 | L39: 644500 | N39: 11634.17 | V39: Transfer to WIP | W39: Transfer to WIP 644500 627301011511 | AE39: 1511 | AF39: 627301011511 | AL39: A01 | AO39: 99999
A40: 0 | B40: 1 | K40: 50 | L40: 644500 | N40: 495.94 | V40: Transfer to WIP | W40: Transfer to WIP 644500 627301013212 | AE40: 3212 | AF40: 627301013212 | AL40: A01 | AO40: 99999
...

Sheet Feb
A1: Kết xuất ZVF59 từ SAP, copy thay dữ liệu từ A2 -> BO210 | G1: (Kết chuyển chi phí)

Sheet Mar
A1: Kết xuất ZVF59 từ SAP, copy thay dữ liệu từ A2 -> BO210 | G1: (K/C chi phí)

Sheet Apr
A1: Kết xuất ZVF59 từ SAP, copy thay dữ liệu từ A2

Sheet May
A1: Kết xuất ZVF59 từ SAP, copy thay dữ liệu từ A2 -> BO210

Sheet Jun
A1: Kết xuất ZVF59 từ SAP, copy thay dữ liệu từ A2 -> cột BN

Sheet Jul
A1: Kết xuất ZVF59 từ SAP, copy thay dữ liệu từ A2 -> cột BN

Sheet Aug
A1: Kết xuất ZVF59 từ SAP, copy thay dữ liệu từ A2 -> cột BN

Sheet Sep
A1: Kết xuất ZVF59 từ SAP, copy thay dữ liệu từ A2 -> cột BN

Sheet Oct
A1: Kết xuất ZVF59 từ SAP, copy thay dữ liệu từ A2 -> cột BN

Sheet Nov
A1: Kết xuất ZVF59 từ SAP, copy thay dữ liệu từ A2 -> cột BN

Sheet Dec
A1: Kết xuất ZVF59 từ SAP, copy thay dữ liệu từ A2 -> cột BN

Sheet Tire Weight
A1: Monthly update
B3: Source: | C3: ..\..\..\..\1-ALL\11. 8411\04. TS-Share\08. TS-ACC\RRW update.xlsx | I3: \\10.118.29.7\BTMV-Data\4-ACCOUNTING\71.Costing\1. Costing calculation\2023\Tire weight report\
B4: Please confirm with Nam-san before input data | I4: Tire Weight Tolerance provided by TS
A5: BPC & BTMV Code | B5: BPC | C5: BTMV Code | D5: Tire weight | E5: RRT | I5: BPC | J5: ACTUAL Weight | K5: Plant Process Weight | L5: %
A7: =B7&"-"&C7 -> PSR0V039-BLFVA | B7: PSR0V039 | C7: BLFVA | D7: 6.895 | E7: 3.438 | I7: PSR0V229 | J7: 4.9413261 | K7: 4.929 | L7: =J7/K7 -> 1.0025007
A8: =B8&"-"&C8 -> PSR0VB0F-D3MVA | B8: PSR0VB0F | C8: D3MVA | D8: 8.778 | E8: 4.099 | I8: PSR0V234 | J8: 5.0941341 | K8: 5.082 | L8: =J8/K8 -> 1.0023877
A9: =B9&"-"&C9 -> PSR0V035-DEFVA | B9: PSR0V035 | C9: DEFVA | D9: 5.538 | E9: 2.726 | I9: PSR0VF6F | J9: 12.209864 | K9: 12.219 | L9: =J9/K9 -> 0.99925234
A10: =B10&"-"&C10 -> PSR0V122-YBGVA | B10: PSR0V122 | C10: YBGVA | D10: 9.02 | E10: 4.267 | I10: PSR0VE9F | J10: 7.2400054 | K10: 7.252 | L10: =J10/K10 -> 0.99834602
A11: =B11&"-"&C11 -> PSR0V11F-EAEVA | B11: PSR0V11F | C11: EAEVA | D11: 6.126 | E11: 3.066 | I11: PSR0VH3F | J11: 8.5335681 | K11: 8.592 | L11: =J11/K11 -> 0.99319927
A12: =B12&"-"&C12 -> PSR0V124-KLTZA | B12: PSR0V124 | C12: KLTZA | D12: 10.268 | E12: 4.481 | I12: PSR0V240 | J12: 6.8673224 | K12: 6.845 | L12: =J12/K12 -> 1.0032611
A13: =B13&"-"&C13 -> PSR0V73F-WMTZA | B13: PSR0V73F | C13: WMTZA | D13: 10.268 | E13: 4.481 | I13: PSR0V05B | J13: 7.5226188 | K13: 7.515 | L13: =J13/K13 -> 1.0010138
A14: =B14&"-"&C14 -> PSR0V18F-GBAVA | B14: PSR0V18F | C14: GBAVA | D14: 7.48 | E14: 3.794 | I14: PSR0V81F | J14: 8.3890386 | K14: 8.39 | L14: =J14/K14 -> 0.99988542
A15: =B15&"-"&C15 -> PSR0V19F-SHTVA | B15: PSR0V19F | C15: SHTVA | D15: 7.48 | E15: 3.794 | I15: PSR0VJ7F | J15: 7.4972794 | K15: 7.608 | L15: =J15/K15 -> 0.98544683
A16: =B16&"-"&C16 -> PSR0VB3F-TENVA | B16: PSR0VB3F | C16: TENVA | D16: 8.318 | E16: 3.951 | I16: PSR0VH9F | J16: 10.112926 | K16: 10.017 | L16: =J16/K16 -> 1.0095763
A17: =B17&"-"&C17 -> PSR0V16D-HGKZA | B17: PSR0V16D | C17: HGKZA | D17: 11.726 | E17: 5.447 | I17: PSR0VH8F | J17: 10.685916 | K17: 10.723 | L17: =J17/K17 -> 0.99654166
A18: =B18&"-"&C18 -> PSR0V109-HPBVA | B18: PSR0V109 | C18: HPBVA | D18: 8.323 | E18: 4.112 | I18: PSR0VJ8F | J18: 7.1398197 | K18: 7.096 | L18: =J18/K18 -> 1.0061753
... A57: =B57&"-"&C57 -> PSR0V02P-QP3VA | B57: PSR0V02P | C57: QP3VA | D57: 8.892 | E57: 4.138 | I57: PSR0V149 | J57: 9.1933144 | K57: 9.116 | L57: =J57/K57 -> 1.0084812
A58: =B58&"-"&C58 -> PSR0VB2F-YK2VA | B58: PSR0VB2F | C58: YK2VA | D58: 7.976 | E58: #N/A | I58: PSR0V50D | J58: 9.235988 | K58: 9.227 | L58: =J58/K58 -> 1.0009741
A59: =B59&"-"&C59 -> PSR0V113-S3NVA | B59: PSR0V113 | C59: S3NVA | D59: 7.397 | E59: 3.623 | I59: PSR0V52D | J59: 9.7224699 | K59: 9.777 | L59: =J59/K59 -> 0.99442261
A60: =B60&"-"&C60 -> PSR0V78F-DKHZA | B60: PSR0V78F | C60: DKHZA | D60: 10.919 | E60: 4.741 | I60: PSR0VF2F | J60: 7.4069531 | K60: 7.506 | L60: =J60/K60 -> 0.98680431
A61: =B61&"-"&C61 -> PSR0V123-PLLZA | B61: PSR0V123 | C61: PLLZA | D61: 10.474 | E61: 5.039 | I61: PSR0V23D | J61: 13.258639 | K61: 13.335 | L61: =J61/K61 -> 0.99427367
A62: =B62&"-"&C62 -> PSR0V74F-JRVZA | B62: PSR0V74F | C62: JRVZA | D62: 12.278 | E62: 5.425 | I62: PSR0V225 | J62: 16.47381 | K62: 16.08 | L62: =J62/K62 -> 1.0244906
A63: =B63&"-"&C63 -> PSR0V92F-GMDVA | B63: PSR0V92F | C63: GMDVA | D63: 9.071 | E63: 4.305 | I63: PSR0V168 | J63: 10.174858 | K63: 10.209 | L63: =J63/K63 -> 0.9966557
A64: =B64&"-"&C64 -> PSR0V87F-EMYVA | B64: PSR0V87F | C64: EMYVA | D64: 8.969 | E64: 4.225 | I64: PSR0V51D | J64: 9.895533 | K64: 9.963 | L64: =J64/K64 -> 0.99322824
A65: =B65&"-"&C65 -> PSR0V85F-TCTVA | B65: PSR0V85F | C65: TCTVA | D65: 11.629 | E65: 5.484 | I65: PSR0V169 | J65: 10.752599 | K65: 10.753 | L65: =J65/K65 -> 0.99996268
A66: =B66&"-"&C66 -> PSR0V80F-VHXVA | B66: PSR0V80F | C66: VHXVA | D66: 10.017 | E66: 4.79 | I66: PSR0VG2F | J66: 12.457596 | K66: 12.435 | L66: =J66/K66 -> 1.0018171
A67: =B67&"-"&C67 -> PSR0V84F-ENGVA | B67: PSR0V84F | C67: ENGVA | D67: 10.09 | E67: 4.832 | I67: PSR0V16D | J67: 11.498491 | K67: 11.471 | L67: =J67/K67 -> 1.0023965
A68: =B68&"-"&C68 -> PSR0VA0F-PCXVA | B68: PSR0VA0F | C68: PCXVA | D68: 8.923 | E68: 4.084 | I68: PSR0V187 | J68: 11.478711 | K68: 11.405 | L68: =J68/K68 -> 1.0064631
A69: =B69&"-"&C69 -> PSR0V83F-VSTVA | B69: PSR0V83F | C69: VSTVA | D69: 7.546 | E69: 3.642 | I69: PSR0V165 | J69: 8.5164055 | K69: 8.512 | L69: =J69/K69 -> 1.0005176
A70: =B70&"-"&C70 -> PSR0V93F-EGGVA | B70: PSR0V93F | C70: EGGVA | D70: 8.732 | E70: 4.048 | I70: PSR0V164 | J70: 11.610099 | K70: 11.557 | L70: =J70/K70 -> 1.0045945
... A88: =B88&"-"&C88 -> PSR0V155-TWWZA | B88: PSR0V155 | C88: TWWZA | D88: 12.435 | E88: 5.539 | I88: PSR0VG6F | J88: 10.918174 | K88: 10.816 | L88: =J88/K88 -> 1.0094466
A89: =B89&"-"&C89 -> PSR0V88F-TDHVA | B89: PSR0V88F | C89: TDHVA | D89: 10.723 | E89: 5.057 | L89: =J89/K89 -> #DIV/0!
A90: =B90&"-"&C90 -> PSR0V81F-WETVA | B90: PSR0V81F | C90: WETVA | D90: 8.39 | E90: 4.052 | I90: PSR0V229 | J90: 4.9614622 | K90: 4.929 | L90: =J90/K90 -> 1.006586
A91: =B91&"-"&C91 -> PSR0V043-WLLVA | B91: PSR0V043 | C91: WLLVA | D91: 8.426 | E91: 4.219 | I91: PSR0V234 | J91: 5.1168214 | K91: 5.074 | L91: =J91/K91 -> 1.0084394
A92: =B92&"-"&C92 -> PSR0V91F-REXVA | B92: PSR0V91F | C92: REXVA | D92: 8.624 | E92: 4.033 | I92: PSR0VE9F | J92: 7.263781 | K92: 7.252 | L92: =J92/K92 -> 1.0016245
A93: =B93&"-"&C93 -> PSR0V005-DLVVA | B93: PSR0V005 | C93: DLVVA | D93: 7.732 | E93: 3.875 | I93: PSR0V86F | J93: 8.8744542 | K93: 8.864 | L93: =J93/K93 -> 1.0011794
A94: =B94&"-"&C94 -> PSR0V114-S4NVA | B94: PSR0V114 | C94: S4NVA | D94: 8.338 | E94: 4.03 | I94: PSR0VF2F | J94: 7.4734964 | K94: 7.506 | L94: =J94/K94 -> 0.99566965
A95: =B95&"-"&C95 -> PSR0V135-XBBVA | B95: PSR0V135 | C95: XBBVA | D95: 10.683 | E95: 5.061 | I95: PSR0V92F | J95: 9.1703563 | K95: 9.071 | L95: =J95/K95 -> 1.0109532
A96: =B96&"-"&C96 -> PSR0V77F-SYTZA | B96: PSR0V77F | C96: SYTZA | D96: 11.92 | E96: 5.244 | I96: PSR0V194 | J96: 8.1236966 | K96: 8.089 | L96: =J96/K96 -> 1.0042894
A97: =B97&"-"&C97 -> PSR0V65F-VKEVA | B97: PSR0V65F | C97: VKEVA | D97: 10.326 | E97: 4.669 | I97: PSR0V87F | J97: 9.0148658 | K97: 8.969 | L97: =J97/K97 -> 1.0051138
...

Sheet DM-Sum
B1: DM COST CALCULATION
B2: Month: | C2: ='FACTORY COST'!G2 -> Jan
E4: Predetermined | G4: Theoretical | I4: Theor. Vs Pre. | K4: Actual | N4: Act vs Theor.
B5: BPC | C5: Pro. Code | D5: Quantities | E5: Cost/Tire | F5: DMC | G5: Cost/Tire | H5: DMC | I5: Gap | J5: % | K5: Tire Wt. % (Act vs. Process) | L5: Unit price | M5: DMC | N5: Gap
B6: PSR0V01B | C6: =VLOOKUP(B6,'MFG COST SUMMARY'!C:E,3,0) -> GSGVA | D6: 433 | E6: 12.295984 | F6: =E6*D6 -> 5324.161 | G6: 9.7010121 | H6: =+D6*G6 -> 4200.5382 | I6: =H6-F6 -> -1123.6227 | J6: =+H6/F6 -> 0.78895778 | K6: =IFERROR(VLOOKUP($B6,'Tire Weight'!$I:$L,4,0),1) -> 1.0007393 | L6: =G6*K6 -> 9.7081839 | M6: =+H6*K6 -> 4203.6436 | N6: =M6-H6 -> 3.1053944
B7: PSR0V01S | C7: =VLOOKUP(B7,'MFG COST SUMMARY'!C:E,3,0) -> P2PVA | D7: 564 | E7: 15.901027 | F7: =E7*D7 -> 8968.1794 | G7: 12.686868 | H7: =+D7*G7 -> 7155.3938 | I7: =H7-F7 -> -1812.7856 | J7: =+H7/F7 -> 0.79786471 | K7: =IFERROR(VLOOKUP($B7,'Tire Weight'!$I:$L,4,0),1) -> 0.99890657 | L7: =G7*K7 -> 12.672996 | M7: =+H7*K7 -> 7147.5699 | N7: =M7-H7 -> -7.8238909
B8: PSR0V03P | C8: =VLOOKUP(B8,'MFG COST SUMMARY'!C:E,3,0) -> BJTVA | D8: 2 | E8: 23.539557 | F8: =E8*D8 -> 47.079114 | G8: 18.906536 | H8: =+D8*G8 -> 37.813073 | I8: =H8-F8 -> -9.2660419 | J8: =+H8/F8 -> 0.80318147 | K8: =IFERROR(VLOOKUP($B8,'Tire Weight'!$I:$L,4,0),1) -> 0.98959061 | L8: =G8*K8 -> 18.709731 | M8: =+H8*K8 -> 37.419461 | N8: =M8-H8 -> -0.39361108
B9: PSR0V03S | C9: =VLOOKUP(B9,'MFG COST SUMMARY'!C:E,3,0) -> VVVVA | D9: 328 | E9: 16.942699 | F9: =E9*D9 -> 5557.2053 | G9: 13.531537 | H9: =+D9*G9 -> 4438.3441 | I9: =H9-F9 -> -1118.8612 | J9: =+H9/F9 -> 0.79866477 | K9: =IFERROR(VLOOKUP($B9,'Tire Weight'!$I:$L,4,0),1) -> 1.0050561 | L9: =G9*K9 -> 13.599954 | M9: =+H9*K9 -> 4460.7848 | N9: =M9-H9 -> 22.440677
B10: PSR0V04P | C10: =VLOOKUP(B10,'MFG COST SUMMARY'!C:E,3,0) -> TZNVA | D10: 1 | E10: 21.690231 | F10: =E10*D10 -> 21.690231 | G10: 17.394403 | H10: =+D10*G10 -> 17.394403 | I10: =H10-F10 -> -4.2958271 | J10: =+H10/F10 -> 0.80194645 | K10: =IFERROR(VLOOKUP($B10,'Tire Weight'!$I:$L,4,0),1) -> 1.0016103 | L10: =G10*K10 -> 17.422414 | M10: =+H10*K10 -> 17.422414 | N10: =M10-H10 -> 0.028010817
B11: PSR0V04S | C11: =VLOOKUP(B11,'MFG COST SUMMARY'!C:E,3,0) -> 3MCVA | D11: 423 | E11: 19.017484 | F11: =E11*D11 -> 8044.3958 | G11: 15.220953 | H11: =+D11*G11 -> 6438.463 | I11: =H11-F11 -> -1605.9328 | J11: =+H11/F11 -> 0.80036627 | K11: =IFERROR(VLOOKUP($B11,'Tire Weight'!$I:$L,4,0),1) -> 1.0052785 | L11: =G11*K11 -> 15.301296 | M11: =+H11*K11 -> 6472.4483 | N11: =M11-H11 -> 33.985324
B12: PSR0V05B | C12: =VLOOKUP(B12,'MFG COST SUMMARY'!C:E,3,0) -> EHSVA | D12: 4421 | E12: 17.370006 | F12: =E12*D12 -> 76792.797 | G12: 13.706193 | H12: =+D12*G12 -> 60595.081 | I12: =H12-F12 -> -16197.716 | J12: =+H12/F12 -> 0.78907246 | K12: =IFERROR(VLOOKUP($B12,'Tire Weight'!$I:$L,4,0),1) -> 1.0010138 | L12: =G12*K12 -> 13.720089 | M12: =+H12*K12 -> 60656.513 | N12: =M12-H12 -> 61.432318
B13: PSR0V05P | C13: =VLOOKUP(B13,'MFG COST SUMMARY'!C:E,3,0) -> JZTVA | D13: 103 | E13: 17.219285 | F13: =E13*D13 -> 1773.5864 | G13: 13.794321 | H13: =+D13*G13 -> 1420.8151 | I13: =H13-F13 -> -352.77127 | J13: =+H13/F13 -> 0.80109722 | K13: =IFERROR(VLOOKUP($B13,'Tire Weight'!$I:$L,4,0),1) -> 0.99869812 | L13: =G13*K13 -> 13.776363 | M13: =+H13*K13 -> 1418.9654 | N13: =M13-H13 -> -1.8497343
B14: PSR0V05S | C14: =VLOOKUP(B14,'MFG COST SUMMARY'!C:E,3,0) -> YYYVA | D14: 913 | E14: 19.332254 | F14: =E14*D14 -> 17650.348 | G14: 15.467715 | H14: =+D14*G14 -> 14122.023 | I14: =H14-F14 -> -3528.3246 | J14: =+H14/F14 -> 0.80009887 | K14: =IFERROR(VLOOKUP($B14,'Tire Weight'!$I:$L,4,0),1) -> 0.9875932 | L14: =G14*K14 -> 15.27581 | M14: =+H14*K14 -> 13946.814 | N14: =M14-H14 -> -175.20917
B15: PSR0V07S | C15: =VLOOKUP(B15,'MFG COST SUMMARY'!C:E,3,0) -> F91VA | D15: 1081 | E15: 24.713618 | F15: =E15*D15 -> 26715.421 | G15: 19.750078 | H15: =+D15*G15 -> 21349.834 | I15: =H15-F15 -> -5365.5869 | J15: =+H15/F15 -> 0.79915769 | K15: =IFERROR(VLOOKUP($B15,'Tire Weight'!$I:$L,4,0),1) -> 1.0053372 | L15: =G15*K15 -> 19.855487 | M15: =+H15*K15 -> 21463.782 | N15: =M15-H15 -> 113.94776
B16: PSR0V11D | C16: =VLOOKUP(B16,'MFG COST SUMMARY'!C:E,3,0) -> VGBVA | D16: 1 | E16: 26.027867 | F16: =E16*D16 -> 26.027867 | G16: 20.514743 | H16: =+D16*G16 -> 20.514743 | I16: =H16-F16 -> -5.5131244 | J16: =+H16/F16 -> 0.78818378 | K16: =IFERROR(VLOOKUP($B16,'Tire Weight'!$I:$L,4,0),1) -> 0.98932835 | L16: =G16*K16 -> 20.295817 | M16: =+H16*K16 -> 20.295817 | N16: =M16-H16 -> -0.21892611
B17: PSR0V11S | C17: =VLOOKUP(B17,'MFG COST SUMMARY'!C:E,3,0) -> YSLVA | D17: 465 | E17: 19.014857 | F17: =E17*D17 -> 8841.9087 | G17: 15.174665 | H17: =+D17*G17 -> 7056.2193 | I17: =H17-F17 -> -1785.6894 | J17: =+H17/F17 -> 0.79804255 | K17: =IFERROR(VLOOKUP($B17,'Tire Weight'!$I:$L,4,0),1) -> 0.99162369 | L17: =G17*K17 -> 15.047558 | M17: =+H17*K17 -> 6997.1142 | N17: =M17-H17 -> -59.105048
... B116: PSR0VH9F | C116: =VLOOKUP(B116,'MFG COST SUMMARY'!C:E,3,0) -> 4HXVA | D116: 3142 | E116: 22.808889 | F116: =E116*D116 -> 71665.528 | G116: 18.199961 | H116: =+D116*G116 -> 57184.277 | I116: =H116-F116 -> -14481.252 | J116: =+H116/F116 -> 0.79793282 | K116: =IFERROR(VLOOKUP($B116,'Tire Weight'!$I:$L,4,0),1) -> 1.0095763 | L116: =G116*K116 -> 18.374249 | M116: =+H116*K116 -> 57731.889 | N116: =M116-H116 -> 547.61266
B117: Total | D117: =SUM(D6:D116) -> 201209 | E117: x | F117: =SUM(F6:F116) -> 3399527.9 | G117: x | H117: =SUM(H6:H116) -> 2728414.3 | I117: =SUM(I6:I116) -> -671113.6 | J117: =+H117/F117 -> 0.80258624 | K117: x | L117: x | M117: =SUM(M6:M116) -> 2731957.5 | N117: =SUM(N6:N116) -> 3543.1565
H118: =H117/F117 -> 0.80258624 | M118: =M117/H117 -> 1.0012986
B119: Check with file DM calculation | D119: 201209 | F119: 3399527.9 | H119: 2728414.3 | M119: =M117/1000 -> 2731.9575
D120: =D117-D119 -> 0 | F120: =F117-F119 -> 0 | H120: =H117-H119 -> 0
B121: Check with sheet MFG Cost Summary | D121: ='MFG COST SUMMARY'!F130 -> 201209
D122: =D117-D121 -> 0

Sheet Rework
A1: Rework tire control
D4: Jan | L4: Feb | T4: Mar | AB4: Apr | AJ4: May | AR4: Jun | AZ4: Jul | BH4: Aug | BP4: Sep | BX4: Oct | CF4: Nov | CN4: Dec
A5: BPC | B5: Open | D5: WH-> Process | F5: Process-> WH | H5: Scrap | J5: Close | L5: WH-> Process | N5: Process-> WH | P5: Scrap | R5: Close | T5: WH-> Process | V5: Process-> WH | X5: Scrap | Z5: Close | AB5: WH-> Process | AD5: Process-> WH | AF5: Scrap | AH5: Close | AJ5: WH-> Process | AL5: Process-> WH | AN5: Scrap | AP5: Close | AR5: WH-> Process | AT5: Process-> WH | AV5: Scrap | AX5: Close | AZ5: WH-> Process | BB5: Process-> WH | BD5: Scrap | BF5: Close | BH5: WH-> Process | BJ5: Process-> WH | BL5: Scrap | BN5: Close | BP5: WH-> Process | BR5: Process-> WH | BT5: Scrap | BV5: Close | BX5: WH-> Process | BZ5: Process-> WH | CB5: Scrap | CD5: Close | CF5: WH-> Process | CH5: Process-> WH | CJ5: Scrap | CL5: Close | CN5: WH-> Process | CP5: Process-> WH | CR5: Scrap | CT5: Close
B6: Q'ty | C6: Am't | D6: Q'ty | E6: Am't | F6: Q'ty | G6: Am't | H6: Q'ty | I6: Am't | J6: Q'ty | K6: Am't | L6: Q'ty | M6: Am't | N6: Q'ty | O6: Am't | P6: Q'ty | Q6: Am't | R6: Q'ty | S6: Am't | T6: Q'ty | U6: Am't | V6: Q'ty | W6: Am't | X6: Q'ty | Y6: Am't | Z6: Q'ty | AA6: Am't | AB6: Q'ty | AC6: Am't | AD6: Q'ty | AE6: Am't | AF6: Q'ty | AG6: Am't | AH6: Q'ty | AI6: Am't | AJ6: Q'ty | AK6: Am't | AL6: Q'ty | AM6: Am't | AN6: Q'ty | AO6: Am't | AP6: Q'ty | AQ6: Am't | AR6: Q'ty | AS6: Am't | AT6: Q'ty | AU6: Am't | AV6: Q'ty | AW6: Am't | AX6: Q'ty | AY6: Am't | AZ6: Q'ty | BA6: Am't | BB6: Q'ty | BC6: Am't | BD6: Q'ty | BE6: Am't | BF6: Q'ty | BG6: Am't | BH6: Q'ty | BI6: Am't | BJ6: Q'ty | BK6: Am't | BL6: Q'ty | BM6: Am't | BN6: Q'ty | BO6: Am't | BP6: Q'ty | BQ6: Am't | BR6: Q'ty | BS6: Am't | BT6: Q'ty | BU6: Am't | BV6: Q'ty | BW6: Am't | BX6: Q'ty | BY6: Am't | BZ6: Q'ty | CA6: Am't | CB6: Q'ty | CC6: Am't | CD6: Q'ty | CE6: Am't | CF6: Q'ty | CG6: Am't | CH6: Q'ty | CI6: Am't | CJ6: Q'ty | CK6: Am't | CL6: Q'ty | CM6: Am't | CN6: Q'ty | CO6: Am't | CP6: Q'ty | CQ6: Am't | CR6: Q'ty | CS6: Am't | CT6: Q'ty | CU6: Am't
A7: PSR0V124 | B7: 13 | C7: 709.93591 | J7: 13 | K7: 709.93591
A8: PSR0V124 | B8: 4 | C8: 175.88 | J8: 4 | K8: 175.88
A9: PSR0V124 | B9: 29 | C9: 1158.3469 | J9: 29 | K9: 1158.3469
A10: PSR0V226 | B10: 4 | C10: 164.585 | J10: 4 | K10: 164.585
A11: PSR0V13D | B11: 1 | C11: 48.987917 | J11: 1 | K11: 48.987917
A12: PSR0V239 | B12: 1 | C12: 31.54 | J12: 1 | K12: 31.54
A13: PSR0V239 | B13: 4 | C13: 126.08 | F13: 4 | G13: 126.08 | J13: 0 | K13: 0
A14: PSR0V178 | B14: 3 | C14: 85.285 | F14: 3 | G14: 85.285 | J14: 0 | K14: 0
A15: PSR0V185 | B15: 5 | C15: 173.45 | F15: 3 | G15: 104.07 | H15: 1 | I15: 34.69 | J15: 1 | K15: 34.69
A16: PSR0V001 | B16: 1 | C16: 20.45 | H16: 1 | I16: 20.45 | J16: 0 | K16: 0
A17: PSR0V012 | B17: 1 | C17: 27.86 | H17: 1 | I17: 27.86 | J17: 0 | K17: 0
A18: PSR0V013 | B18: 1 | C18: 33.4 | H18: 1 | I18: 33.4 | J18: 0 | K18: 0
A19: PSR0V014 | B19: 1 | C19: 38.03 | H19: 1 | I19: 38.03 | J19: 0 | K19: 0
A20: PSR0V004 | B20: 1 | C20: 31.93 | H20: 1 | I20: 31.93 | J20: 0 | K20: 0
A21: PSR0V043 | B21: 1 | C21: 36.61 | H21: 1 | I21: 36.61 | J21: 0 | K21: 0
A22: PSR0V002 | B22: 1 | C22: 23.95 | H22: 1 | I22: 23.95 | J22: 0 | K22: 0
A23: PSR0V231 | B23: 1 | C23: 29.85 | H23: 1 | I23: 29.85 | J23: 0 | K23: 0
A24: PSR0V18D | B24: 1 | C24: 43.43 | J24: 1 | K24: 43.43
A25: PSR0V04P | B25: 1 | C25: 36.04 | J25: 1 | K25: 36.04
A26: PSR0V236 | B26: 1 | C26: 27.49 | F26: 1 | G26: 27.49 | J26: 0 | K26: 0
A27: PSR0V221 | B27: 0 | C27: 0 | D27: 7 | E27: 321.93 | J27: 7 | K27: 321.93
A28: PSR0V29D | B28: 0 | C28: 0 | D28: 1 | E28: 45.46 | J28: 1 | K28: 45.46
A29: PSR0V210 | B29: 0 | C29: 0 | D29: 4 | E29: 210 | H29: 4 | I29: 210 | J29: 0 | K29: 0
J43: =B43+D43-F43-H43 -> 0 | K43: =C43+E43-G43-I43 -> 0 | R43: =J43+L43-N43-P43 -> 0 | S43: =K43+M43-O43-Q43 -> 0 | Z43: =R43+T43-V43-X43 -> 0 | AA43: =S43+U43-W43-Y43 -> 0 | AH43: =Z43+AB43-AD43-AF43 -> 0 | AI43: =AA43+AC43-AE43-AG43 -> 0 | AP43: =AH43+AJ43-AL43-AN43 -> 0 | AQ43: =AI43+AK43-AM43-AO43 -> 0 | AX43: =AP43+AR43-AT43-AV43 -> 0 | AY43: =AQ43+AS43-AU43-AW43 -> 0 | BF43: =AX43+AZ43-BB43-BD43 -> 0 | BG43: =AY43+BA43-BC43-BE43 -> 0 | BN43: =BF43+BH43-BJ43-BL43 -> 0 | BO43: =BG43+BI43-BK43-BM43 -> 0 | BV43: =BN43+BP43-BR43-BT43 -> 0 | BW43: =BO43+BQ43-BS43-BU43 -> 0 | CD43: =BV43+BX43-BZ43-CB43 -> 0 | CE43: =BW43+BY43-CA43-CC43 -> 0 | CL43: =CD43+CF43-CH43-CJ43 -> 0 | CM43: =CE43+CG43-CI43-CK43 -> 0 | CT43: =CL43+CN43-CP43-CR43 -> 0 | CU43: =CM43+CO43-CQ43-CS43 -> 0
A44: Total | B44: =SUBTOTAL(9,B7:B43) -> 75 | C44: =SUBTOTAL(9,C7:C43) -> 3023.1307 | D44: =SUBTOTAL(9,D7:D43) -> 12 | E44: =SUBTOTAL(9,E7:E43) -> 577.39 | F44: =SUBTOTAL(9,F7:F43) -> 11 | G44: =SUBTOTAL(9,G7:G43) -> 342.925 | H44: =SUBTOTAL(9,H7:H43) -> 13 | I44: =SUBTOTAL(9,I7:I43) -> 486.77 | ... CU44: =SUBTOTAL(9,CU7:CU43) -> 0
CH45: =CF44-CH44 -> 0 | CI45: =CG44-CI44 -> 0

Sheet Cured tire BSTVN
A2: Cured tire_Sep.22
A3: Data source: | B3: ..\..\5.Standard & TPL\Seme-products price\2022\Aug 2022\26EZA.xlsx
C5: Number | D5: Brand name | E5: MTP group | F5: BTMV code | G5: M3 | H5: Tire weight | I5: RRW | J5: Cost (USD)/unit | P5: Total cost (USD)
C6: (PCs) | I6: (g) | J6: DM cost | K6: Conversion cost | N6: WS | O6: Factory cost | P6: DM cost | Q6: Conversion cost | T6: WS | U6: Factory cost
K7: Labor | L7: Dep. | M7: Other | Q7: Labor | R7: Dep. | S7: Other
A8: PSR0V244 | B8: 103W 235/60R18 AL01Z | C8: 4 | D8: BRIDGESTONE | E8: PSR2 | F8: 26EZA | H8: 13456 | I8: 6296.1484 | J8: 30.481687 | K8: 5.6200704 | L8: 11.803505 | M8: 7.26149 | N8: 0.8405578 | O8: =SUM(J8:N8) -> 56.00731 | P8: =J8*$C8+0.01 -> 121.93675 | Q8: =K8*$C8 -> 22.480282 | R8: =L8*$C8 -> 47.21402 | S8: =M8*$C8 -> 29.04596 | T8: =N8*$C8 -> 3.3622312 | U8: =+ROUND(SUM(P8:T8),2) -> 224.04

Sheet Budget
A1: 24OB | B1: Production Volume (Pcs) | C1: Production Rubber Tonnage | E1: RBAC2 | F1: Production Volume (Pcs) | G1: Production Rubber Tonnage | I1: RBAC3 | J1: Production Volume (Pcs) | K1: Production Rubber Tonnage | M1: RBAC4 | N1: Production Volume (Pcs) | O1: Production Rubber Tonnage
A2: Jan | B2: 206640 | C2: 795.42376 | E2: Jan | I2: Jan | M2: Jan
A3: Feb | B3: 146880 | C3: 574.30178 | E3: Feb | I3: Feb | M3: Feb
A4: Mar | B4: 223200 | C4: 775.89055 | E4: Mar | I4: Mar | M4: Mar
A5: Apr | B5: 190800 | C5: 775.16231 | E5: Apr | I5: Apr | M5: Apr
A6: May | B6: 198720 | C6: 758.40554 | E6: May | I6: May | M6: May
A7: Jun | B7: 216000 | C7: 855.31156 | E7: Jun | I7: Jun | M7: Jun
A8: Jul | B8: 241800 | C8: 955.5536 | E8: Jul | I8: Jul | M8: Jul
A9: Aug | B9: 240240 | C9: 931.35916 | E9: Aug | I9: Aug | M9: Aug
A10: Sep | B10: 191880 | C10: 753.77863 | E10: Sep | I10: Sep | M10: Sep
A11: Oct | B11: 241800 | C11: 984.66693 | E11: Oct | I11: Oct | M11: Oct
A12: Nov | B12: 234000 | C12: 916.19473 | E12: Nov | I12: Nov | M12: Nov
A13: Dec | B13: 231660 | C13: 902.54425 | E13: Dec | I13: Dec | M13: Dec

Sheet Result

Sheet FACTORY COST
F1: FACTORY COST DATA
F2: Month: | G2: Jan | U2: =MATCH($G$2,$I$5:$T$5,0) -> 1 | AI2: =+AH3/AI3 -> 0.89342208 | AJ2: =AH3/AJ3 -> 0.86500477
F3: YTD: | G3: Jan_Jan-24 | I3: =+I9/(I9+I8) -> 0.032177732 | J3: =+J9/(J9+J8) -> #DIV/0! | K3: =+K9/(K9+K8) -> #DIV/0! | L3: =+L9/(L9+L8) -> #DIV/0! | M3: =+M9/(M9+M8) -> #DIV/0! | N3: =+N9/(N9+N8) -> #DIV/0! | O3: =+O9/(O9+O8) -> #DIV/0! | P3: =+P9/(P9+P8) -> #DIV/0! | ... T3: =+T9/(T9+T8) -> #DIV/0! | AF3: → ▲ | AH3: ='MFG COST SUMMARY'!J134 -> 688.04535 | AI3: 770.12351 | AJ3: {=INDEX($AT$3:$BE$3,ROW()-2,MATCH($G$2,$AT$5:$BE$5,0))} -> 795.42376 | AT3: =INDEX(Budget!$C$2:$C$13,MATCH(AT$5,Budget!$M$2:$M$13,0)) -> 795.42376 | AU3: =INDEX(Budget!$C$2:$C$13,MATCH(AU$5,Budget!$M$2:$M$13,0)) -> 574.30178 | AV3: =INDEX(Budget!$C$2:$C$13,MATCH(AV$5,Budget!$M$2:$M$13,0)) -> 775.89055 | AW3: =INDEX(Budget!$C$2:$C$13,MATCH(AW$5,Budget!$M$2:$M$13,0)) -> 775.16231 | AX3: =INDEX(Budget!$C$2:$C$13,MATCH(AX$5,Budget!$M$2:$M$13,0)) -> 758.40554 | AY3: =INDEX(Budget!$C$2:$C$13,MATCH(AY$5,Budget!$M$2:$M$13,0)) -> 855.31156 | AZ3: =INDEX(Budget!$C$2:$C$13,MATCH(AZ$5,Budget!$M$2:$M$13,0)) -> 955.5536 | BA3: =INDEX(Budget!$C$2:$C$13,MATCH(BA$5,Budget!$M$2:$M$13,0)) -> 931.35916 | ... BE3: =INDEX(Budget!$C$2:$C$13,MATCH(BE$5,Budget!$M$2:$M$13,0)) -> 902.54425
I4: =CurYear & "_ACT" -> 2024_ACT | Z4: vs. previous month | AD4: ="vs. "&$AT$4 -> vs. 24OB | AH4: Gentan-i | AL4: YTD | AR4: ="Remaining "&$AT$4 -> Remaining 24OB | AT4: 24OB | BG4: =$AT$4&"_Accumulated" -> 24OB_Accumulated
A5: MD code | B5: TD code1 | C5: Mfg_Code | D5: Allot key | E5: SAP code | F5: Acc. No | G5: Description | H5: 2023 Dec | I5: Jan | J5: Feb | K5: Mar | L5: Apr | M5: May | N5: Jun | O5: Jul | P5: Aug | Q5: Sep | R5: Oct | S5: Nov | T5: Dec | U5: ="Total cost " &G2&" "& CurYear -> Total cost Jan 2024 | V5: Opn WIP & SOJ | W5: Cls WIP & SOJ | X5: After Adjustment | Z5: % | AA5: Gap | AB5: Reason | AD5: % | AE5: Gap | AF5: Reason | AH5: =G2 -> Jan | AI5: Previous month | AJ5: =$AT$4 -> 24OB | AL5: =G3 -> Jan_Jan-24 | AN5: ="Vs "&$AT$4 -> Vs 24OB | AP5: Reason | AT5: Jan | AU5: Feb | AV5: Mar | AW5: Apr | AX5: May | AY5: Jun | AZ5: Jul | BA5: Aug | BB5: Sep | BC5: Oct | BD5: Nov | BE5: Dec | BG5: Jan_Feb-24 | BH5: Jan_Mar-24 | BI5: Jan_Apr-24 | BJ5: Jan_May-24 | BK5: Jan_Jun-24 | BL5: Jan_Jul-24 | BM5: Jan_Aug-24 | BN5: Jan_Sep-24 | BO5: Jan_Oct-24 | BP5: Jan_Nov-24 | BQ5: Jan_Dec-24
F7: 154 | H7: =+SUBTOTAL(9,H8:H83) -> 6559483 | I7: =+SUBTOTAL(9,I8:I83) -> 6314761.3 | J7: =+SUBTOTAL(9,J8:J83) -> 0 | K7: =+SUBTOTAL(9,K8:K83) -> 0 | L7: =+SUBTOTAL(9,L8:L83) -> 0 | M7: =+SUBTOTAL(9,M8:M83) -> 0 | N7: =+SUBTOTAL(9,N8:N83) -> 0 | O7: =+SUBTOTAL(9,O8:O83) -> 0 | ... T7: =+SUBTOTAL(9,T8:T83) -> 0 | U7: =SUBTOTAL(9,U8:U83) -> 6314761.3 | V7: =+SUBTOTAL(9,V8:V83) -> 0 | W7: =+SUBTOTAL(9,W8:W83) -> 0 | X7: =+SUBTOTAL(9,X8:X83) -> 6314761.3 | Z7: {=IFERROR(U7/OFFSET($H7:$U7,,MATCH($G$2,$H$5:$U$5,0)-2,,1),"-")} -> 0.96269192 | AA7: =SUBTOTAL(9,AA8:AA83) -> -244721.72 | AD7: {=IFERROR(U7/OFFSET($AT7,,MATCH($G$2,$AT$5:$BE$5,0)-1,,),"-")} -> 0.89681435 | AE7: =SUBTOTAL(9,AE8:AE83) -> -726563.67 | AL7: ="Act "&LEFT(AL5,7) -> Act Jan_Jan | AM7: =$AT$4&" "&LEFT(AL5,7) -> 24OB Jan_Jan | AN7: Var | AO7: % | AR7: =+SUBTOTAL(9,AR8:AR83) -> 84683860 | AT7: =+SUBTOTAL(9,AT8:AT83) -> 7041324.9 | AU7: =+SUBTOTAL(9,AU8:AU83) -> 5877425.3 | AV7: =+SUBTOTAL(9,AV8:AV83) -> 7213914.5 | AW7: =+SUBTOTAL(9,AW8:AW83) -> 7420362.1 | AX7: =+SUBTOTAL(9,AX8:AX83) -> 7288949.7 | AY7: =+SUBTOTAL(9,AY8:AY83) -> 7857651.5 | AZ7: =+SUBTOTAL(9,AZ8:AZ83) -> 8202511.5 | BA7: =+SUBTOTAL(9,BA8:BA83) -> 8137536.8 | ... BE7: =+SUBTOTAL(9,BE8:BE83) -> 8473594.7 | BG7: =+SUBTOTAL(9,BG8:BG83) -> 12918750 | BH7: =+SUBTOTAL(9,BH8:BH83) -> 20132665 | BI7: =+SUBTOTAL(9,BI8:BI83) -> 27553027 | BJ7: =+SUBTOTAL(9,BJ8:BJ83) -> 34841977 | BK7: =+SUBTOTAL(9,BK8:BK83) -> 42699628 | BL7: =+SUBTOTAL(9,BL8:BL83) -> 50902140 | BM7: =+SUBTOTAL(9,BM8:BM83) -> 59039676 | BN7: =+SUBTOTAL(9,BN8:BN83) -> 66222385 | ... BQ7: =+SUBTOTAL(9,BQ8:BQ83) -> 90998622 | BS7: Setting | BW7: 2024
A8: Direct Material cost | B8: Direct Material cost | C8: Direct Material | D8: DM | E8: 600000 | F8: 62100100 | G8: Direct material for mass production | H8: 2496210.4 | I8: =SUMIFS(INDIRECT(I$5&"!N:N"),INDIRECT(I$5&"!L:L"),$E8,INDIRECT(I$5&"!K:K"),50)-SUMIFS(INDIRECT(I$5&"!N:N"),INDIRECT(I$5&"!L:L"),$E8,INDIRECT(I$5&"!K:K"),40) -> 2981091.5 | J8: =SUMIFS(INDIRECT(J$5&"!N:N"),INDIRECT(J$5&"!L:L"),$E8,INDIRECT(J$5&"!K:K"),50)-SUMIFS(INDIRECT(J$5&"!N:N"),INDIRECT(J$5&"!L:L"),$E8,INDIRECT(J$5&"!K:K"),40) -> 0 | K8: =SUMIFS(INDIRECT(K$5&"!N:N"),INDIRECT(K$5&"!L:L"),$E8,INDIRECT(K$5&"!K:K"),50)-SUMIFS(INDIRECT(K$5&"!N:N"),INDIRECT(K$5&"!L:L"),$E8,INDIRECT(K$5&"!K:K"),40) -> 0 | L8: =SUMIFS(INDIRECT(L$5&"!N:N"),INDIRECT(L$5&"!L:L"),$E8,INDIRECT(L$5&"!K:K"),50)-SUMIFS(INDIRECT(L$5&"!N:N"),INDIRECT(L$5&"!L:L"),$E8,INDIRECT(L$5&"!K:K"),40) -> 0 | M8: =SUMIFS(INDIRECT(M$5&"!N:N"),INDIRECT(M$5&"!L:L"),$E8,INDIRECT(M$5&"!K:K"),50)-SUMIFS(INDIRECT(M$5&"!N:N"),INDIRECT(M$5&"!L:L"),$E8,INDIRECT(M$5&"!K:K"),40) -> 0 | N8: =SUMIFS(INDIRECT(N$5&"!N:N"),INDIRECT(N$5&"!L:L"),$E8,INDIRECT(N$5&"!K:K"),50)-SUMIFS(INDIRECT(N$5&"!N:N"),INDIRECT(N$5&"!L:L"),$E8,INDIRECT(N$5&"!K:K"),40) -> 0 | O8: =SUMIFS(INDIRECT(O$5&"!N:N"),INDIRECT(O$5&"!L:L"),$E8,INDIRECT(O$5&"!K:K"),50)-SUMIFS(INDIRECT(O$5&"!N:N"),INDIRECT(O$5&"!L:L"),$E8,INDIRECT(O$5&"!K:K"),40) -> 0 | P8: =SUMIFS(INDIRECT(P$5&"!N:N"),INDIRECT(P$5&"!L:L"),$E8,INDIRECT(P$5&"!K:K"),50)-SUMIFS(INDIRECT(P$5&"!N:N"),INDIRECT(P$5&"!L:L"),$E8,INDIRECT(P$5&"!K:K"),40) -> 0 | ... T8: =SUMIFS(INDIRECT(T$5&"!N:N"),INDIRECT(T$5&"!L:L"),$E8,INDIRECT(T$5&"!K:K"),50)-SUMIFS(INDIRECT(T$5&"!N:N"),INDIRECT(T$5&"!L:L"),$E8,INDIRECT(T$5&"!K:K"),40) -> 0 | U8: {=INDEX($I8:$T8,$U$2)} -> 2981091.5 | X8: =U8+V8-W8 -> 2981091.5 | Z8: {=IFERROR(U8/OFFSET($H8,,MATCH($G$2,$H$5:$U$5,0)-2,,),"-")} -> 1.1942469 | AA8: {=U8-OFFSET($H8,,MATCH($G$2,$H$5:$U$5,0)-2,,)} -> 484881.11 | AD8: {=IFERROR(U8/OFFSET($AT8,,MATCH($G$2,$AT$5:$BE$5,0)-1,,),"-")} -> 0.88715729 | AE8: {=U8-OFFSET($AT8,,MATCH($G$2,$AT$5:$BE$5,0)-1,,)} -> -379182.41 | AH8: {=IFERROR(INDEX($I8:$T8,$U$2)/$AH$3,0)} -> 4332.6963 | AI8: =H8/PrvMonthProductionRRT -> 3241.3118 | AJ8: {=IFERROR(OFFSET($AT8,,MATCH($G$2,$AT$5:$BE$5,0)-1,,)/$AJ$3,"")} -> 4224.5079 | AL8: =SUM(I8:T8) -> 2981091.5 | AM8: {=INDEX($BG$8:$BQ$83,ROW()-7,MATCH($G$3,$BG$5:$BQ$5,0))} -> #N/A | AN8: =AL8-AM8 -> #N/A | AO8: =IFERROR(AL8/AM8,"") | AR8: =BQ8-AL8 -> 39616124 | AT8: 3360274 | AU8: 2470065.1 | AV8: 3397741.4 | AW8: 3331787.6 | AX8: 3249758.5 | AY8: 3678343.1 | AZ8: 4076030.5 | BA8: 3955084 | BB8: 3199182.3 | BC8: 4172372.4 | BD8: 3877777.5 | BE8: 3828798.7 | BG8: =SUM(AT8:AU8) -> 5830339 | BH8: =SUM(AT8:AV8) -> 9228080.4 | BI8: =SUM(AT8:AW8) -> 12559868 | BJ8: =SUM(AT8:AX8) -> 15809627 | BK8: =SUM(AT8:AY8) -> 19487970 | BL8: =SUM(AT8:AZ8) -> 23564000 | BM8: =SUM(AT8:BA8) -> 27519084 | BN8: =SUM(AT8:BB8) -> 30718266 | BO8: =SUM(AT8:BC8) -> 34890639 | BP8: =SUM(AT8:BD8) -> 38768416 | BQ8: =SUM(AT8:BE8) -> 42597215 | BS8: 1 | BT8: Jan | BU8: 1 | BW8: =$BT$8&"_"&BT8&"-"&RIGHT($BW$7,2) -> Jan_Jan-24
A9: Scrap Cost (g) | B9: Scrap Cost | C9: Waste | D9: Waste | E9: 691200 | F9: 62100200 | G9: Direct material loss (W&S) | H9: 107427.44 | I9: =SUMIFS(INDIRECT(I$5&"!N:N"),INDIRECT(I$5&"!L:L"),$E9,INDIRECT(I$5&"!K:K"),50)-SUMIFS(INDIRECT(I$5&"!N:N"),INDIRECT(I$5&"!L:L"),$E9,INDIRECT(I$5&"!K:K"),40) -> 99114.03 | J9: =SUMIFS(INDIRECT(J$5&"!N:N"),INDIRECT(J$5&"!L:L"),$E9,INDIRECT(J$5&"!K:K"),50)-SUMIFS(INDIRECT(J$5&"!N:N"),INDIRECT(J$5&"!L:L"),$E9,INDIRECT(J$5&"!K:K"),40) -> 0 | K9: =SUMIFS(INDIRECT(K$5&"!N:N"),INDIRECT(K$5&"!L:L"),$E9,INDIRECT(K$5&"!K:K"),50)-SUMIFS(INDIRECT(K$5&"!N:N"),INDIRECT(K$5&"!L:L"),$E9,INDIRECT(K$5&"!K:K"),40) -> 0 | L9: =SUMIFS(INDIRECT(L$5&"!N:N"),INDIRECT(L$5&"!L:L"),$E9,INDIRECT(L$5&"!K:K"),50)-SUMIFS(INDIRECT(L$5&"!N:N"),INDIRECT(L$5&"!L:L"),$E9,INDIRECT(L$5&"!K:K"),40) -> 0 | M9: =SUMIFS(INDIRECT(M$5&"!N:N"),INDIRECT(M$5&"!L:L"),$E9,INDIRECT(M$5&"!K:K"),50)-SUMIFS(INDIRECT(M$5&"!N:N"),INDIRECT(M$5&"!L:L"),$E9,INDIRECT(M$5&"!K:K"),40) -> 0 | N9: =SUMIFS(INDIRECT(N$5&"!N:N"),INDIRECT(N$5&"!L:L"),$E9,INDIRECT(N$5&"!K:K"),50)-SUMIFS(INDIRECT(N$5&"!N:N"),INDIRECT(N$5&"!L:L"),$E9,INDIRECT(N$5&"!K:K"),40) -> 0 | O9: =SUMIFS(INDIRECT(O$5&"!N:N"),INDIRECT(O$5&"!L:L"),$E9,INDIRECT(O$5&"!K:K"),50)-SUMIFS(INDIRECT(O$5&"!N:N"),INDIRECT(O$5&"!L:L"),$E9,INDIRECT(O$5&"!K:K"),40) -> 0 | P9: =SUMIFS(INDIRECT(P$5&"!N:N"),INDIRECT(P$5&"!L:L"),$E9,INDIRECT(P$5&"!K:K"),50)-SUMIFS(INDIRECT(P$5&"!N:N"),INDIRECT(P$5&"!L:L"),$E9,INDIRECT(P$5&"!K:K"),40) -> 0 | ... T9: =SUMIFS(INDIRECT(T$5&"!N:N"),INDIRECT(T$5&"!L:L"),$E9,INDIRECT(T$5&"!K:K"),50)-SUMIFS(INDIRECT(T$5&"!N:N"),INDIRECT(T$5&"!L:L"),$E9,INDIRECT(T$5&"!K:K"),40) -> 0 | U9: {=INDEX($I9:$T9,$U$2)} -> 99114.03 | X9: =U9+V9-W9 -> 99114.03 | Z9: {=IFERROR(U9/OFFSET($H9,,MATCH($G$2,$H$5:$U$5,0)-2,,),"-")} -> 0.92261372 | AA9: {=U9-OFFSET($H9,,MATCH($G$2,$H$5:$U$5,0)-2,,)} -> -8313.41 | AD9: {=IFERROR(U9/OFFSET($AT9,,MATCH($G$2,$AT$5:$BE$5,0)-1,,),"-")} -> 0.98063495 | AE9: {=U9-OFFSET($AT9,,MATCH($G$2,$AT$5:$BE$5,0)-1,,)} -> -1957.2508 | AH9: {=IFERROR(INDEX($I9:$T9,$U$2)/$AH$3,0)} -> 144.0516 | AI9: =H9/PrvMonthProductionRRT -> 139.49378 | AJ9: {=IFERROR(OFFSET($AT9,,MATCH($G$2,$AT$5:$BE$5,0)-1,,)/$AJ$3,"")} -> 127.06596 | AL9: =SUM(I9:T9) -> 99114.03 | AM9: {=INDEX($BG$8:$BQ$83,ROW()-7,MATCH($G$3,$BG$5:$BQ$5,0))} -> #N/A | AN9: =AL9-AM9 -> #N/A | AO9: =IFERROR(AL9/AM9,"") | AR9: =BQ9-AL9 -> 1184276.5 | AT9: 101071.28 | AU9: 73771.253 | AV9: 101477.34 | AW9: 101275.36 | AX9: 99472.151 | AY9: 112200.08 | AZ9: 123465.17 | BA9: 119381.85 | BB9: 96565.408 | BC9: 123727.68 | BD9: 116225.49 | BE9: 114757.49 | BG9: =SUM(AT9:AU9) -> 174842.53 | BH9: =SUM(AT9:AV9) -> 276319.88 | BI9: =SUM(AT9:AW9) -> 377595.24 | BJ9: =SUM(AT9:AX9) -> 477067.39 | BK9: =SUM(AT9:AY9) -> 589267.46 | BL9: =SUM(AT9:AZ9) -> 712732.64 | BM9: =SUM(AT9:BA9) -> 832114.49 | BN9: =SUM(AT9:BB9) -> 928679.89 | BO9: =SUM(AT9:BC9) -> 1052407.6 | BP9: =SUM(AT9:BD9) -> 1168633.1 | BQ9: =SUM(AT9:BE9) -> 1283390.5 | BS9: 2 | BT9: Feb | BU9: 2 | BW9: =$BT$8&"_"&BT9&"-"&RIGHT($BW$7,2) -> Jan_Feb-24
